Workbook

Sheet dataset_1
A1: instant | B1: dteday | C1: season | D1: yr | E1: mnth | F1: hr | G1: holiday | H1: weekday | I1: weathersit | J1: temp
A2: 1 | B2: 40544 | C2: 1 | D2: 0 | E2: 1 | F2: 0 | G2: =FALSE() -> FALSE | H2: 6 | I2: 1 | J2: 0.24
A3: 2 | B3: 40544 | C3: 1 | D3: 0 | E3: 1 | F3: 1 | G3: =FALSE() -> FALSE | H3: 6 | I3: 1 | J3: 0.22
A4: 3 | B4: 40544 | C4: 1 | D4: 0 | E4: 1 | F4: 2 | G4: =FALSE() -> FALSE | H4: 6 | I4: 1 | J4: 0.22 | M4: Instant Blank Count | N4: =COUNTBLANK(A2:A611) -> 0
A5: 4 | B5: 40544 | C5: 1 | D5: 0 | E5: 1 | F5: 3 | G5: =FALSE() -> FALSE | H5: 6 | I5: 1 | J5: 0.24
A6: 5 | B6: 40544 | C6: 1 | D6: 0 | E6: 1 | F6: 4 | G6: =FALSE() -> FALSE | H6: 6 | I6: 1 | J6: 0.24
A7: 6 | B7: 40544 | C7: 1 | D7: 0 | E7: 1 | F7: 5 | G7: =FALSE() -> FALSE | H7: 6 | I7: 2 | J7: 0.24
A8: 7 | B8: 40544 | C8: 1 | D8: 0 | E8: 1 | F8: 6 | G8: =FALSE() -> FALSE | H8: 6 | I8: 1 | J8: 0.22
A9: 8 | B9: 40544 | C9: 1 | D9: 0 | E9: 1 | F9: 7 | G9: =FALSE() -> FALSE | H9: 6 | I9: 1 | J9: 0.2
A10: 9 | B10: 40544 | C10: 1 | D10: 0 | E10: 1 | F10: 8 | G10: =FALSE() -> FALSE | H10: 6 | I10: 1 | J10: 0.24
A11: 10 | B11: 40544 | C11: 1 | D11: 0 | E11: 1 | F11: 9 | G11: =FALSE() -> FALSE | H11: 6 | I11: 1 | J11: 0.32
A12: 11 | B12: 40544 | C12: 1 | D12: 0 | E12: 1 | F12: 10 | G12: =FALSE() -> FALSE | H12: 6 | I12: 1 | J12: 0.38
A13: 12 | B13: 40544 | C13: 1 | D13: 0 | E13: 1 | F13: 11 | G13: =FALSE() -> FALSE | H13: 6 | I13: 1 | J13: 0.36
A14: 13 | B14: 40544 | C14: 1 | D14: 0 | E14: 1 | F14: 12 | G14: =FALSE() -> FALSE | H14: 6 | I14: 1 | J14: 0.42
A15: 14 | B15: 40544 | C15: 1 | D15: 0 | E15: 1 | F15: 13 | G15: =FALSE() -> FALSE | H15: 6 | I15: 2 | J15: 0.46
A16: 15 | B16: 40544 | C16: 1 | D16: 0 | E16: 1 | F16: 14 | G16: =FALSE() -> FALSE | H16: 6 | I16: 2 | J16: 0.46
... A373: 372 | B373: 40559 | C373: 1 | D373: 0 | E373: 1 | F373: 23 | G373: =FALSE() -> FALSE | H373: 0 | I373: 2 | J373: 0.2
A374: 373 | B374: 40560 | C374: 1 | D374: 0 | E374: 1 | F374: 0 | G374: =TRUE() -> TRUE | H374: 1 | I374: 2 | J374: 0.2
A375: 374 | B375: 40560 | C375: 1 | D375: 0 | E375: 1 | F375: 1 | G375: =TRUE() -> TRUE | H375: 1 | I375: 2 | J375: 0.2
A376: 375 | B376: 40560 | C376: 1 | D376: 0 | E376: 1 | F376: 2 | G376: =TRUE() -> TRUE | H376: 1 | I376: 2 | J376: 0.18
A377: 376 | B377: 40560 | C377: 1 | D377: 0 | E377: 1 | F377: 3 | G377: =TRUE() -> TRUE | H377: 1 | I377: 2 | J377: 0.18
A378: 377 | B378: 40560 | C378: 1 | D378: 0 | E378: 1 | F378: 4 | G378: =TRUE() -> TRUE | H378: 1 | I378: 2 | J378: 0.18
A379: 378 | B379: 40560 | C379: 1 | D379: 0 | E379: 1 | F379: 5 | G379: =TRUE() -> TRUE | H379: 1 | I379: 2 | J379: 0.18
A380: 379 | B380: 40560 | C380: 1 | D380: 0 | E380: 1 | F380: 6 | G380: =TRUE() -> TRUE | H380: 1 | I380: 2 | J380: 0.18
A381: 380 | B381: 40560 | C381: 1 | D381: 0 | E381: 1 | F381: 7 | G381: =TRUE() -> TRUE | H381: 1 | I381: 2 | J381: 0.16
A382: 381 | B382: 40560 | C382: 1 | D382: 0 | E382: 1 | F382: 8 | G382: =TRUE() -> TRUE | H382: 1 | I382: 2 | J382: 0.16
A383: 382 | B383: 40560 | C383: 1 | D383: 0 | E383: 1 | F383: 9 | G383: =TRUE() -> TRUE | H383: 1 | I383: 2 | J383: 0.16
A384: 383 | B384: 40560 | C384: 1 | D384: 0 | E384: 1 | F384: 10 | G384: =TRUE() -> TRUE | H384: 1 | I384: 2 | J384: 0.16
A385: 384 | B385: 40560 | C385: 1 | D385: 0 | E385: 1 | F385: 11 | G385: =TRUE() -> TRUE | H385: 1 | I385: 2 | J385: 0.16
... A397: 396 | B397: 40560 | C397: 1 | D397: 0 | E397: 1 | F397: 23 | G397: =TRUE() -> TRUE | H397: 1 | I397: 3 | J397: 0.16
A398: 397 | B398: 40561 | C398: 1 | D398: 0 | E398: 1 | F398: 12 | G398: =FALSE() -> FALSE | H398: 2 | I398: 2 | J398: 0.2
A399: 398 | B399: 40561 | C399: 1 | D399: 0 | E399: 1 | F399: 13 | G399: =FALSE() -> FALSE | H399: 2 | I399: 2 | J399: 0.2
A400: 399 | B400: 40561 | C400: 1 | D400: 0 | E400: 1 | F400: 14 | G400: =FALSE() -> FALSE | H400: 2 | I400: 2 | J400: 0.22
A401: 400 | B401: 40561 | C401: 1 | D401: 0 | E401: 1 | F401: 15 | G401: =FALSE() -> FALSE | H401: 2 | I401: 2 | J401: 0.22
A402: 401 | B402: 40561 | C402: 1 | D402: 0 | E402: 1 | F402: 16 | G402: =FALSE() -> FALSE | H402: 2 | I402: 2 | J402: 0.22
A403: 402 | B403: 40561 | C403: 1 | D403: 0 | E403: 1 | F403: 17 | G403: =FALSE() -> FALSE | H403: 2 | I403: 2 | J403: 0.22
A404: 403 | B404: 40561 | C404: 1 | D404: 0 | E404: 1 | F404: 18 | G404: =FALSE() -> FALSE | H404: 2 | I404: 2 | J404: 0.22
A405: 404 | B405: 40561 | C405: 1 | D405: 0 | E405: 1 | F405: 19 | G405: =FALSE() -> FALSE | H405: 2 | I405: 2 | J405: 0.22
A406: 405 | B406: 40561 | C406: 1 | D406: 0 | E406: 1 | F406: 20 | G406: =FALSE() -> FALSE | H406: 2 | I406: 2 | J406: 0.22
A407: 406 | B407: 40561 | C407: 1 | D407: 0 | E407: 1 | F407: 21 | G407: =FALSE() -> FALSE | H407: 2 | I407: 2 | J407: 0.22
...

Sheet dataset_2
A1: instant | B1: atemp | C1: hum | D1: windspeed | E1: casual | F1: registered | G1: cnt | H1: Check Total | I1: Total Errors
A2: 1 | B2: 0.2879 | C2: 0.81 | D2: 0 | E2: 3 | F2: 13 | G2: 16 | H2: =IF(E2+F2=G2, "Ok", "Error") -> Ok | I2: =COUNTIF(H2:H610,"Error") -> 0
A3: 2 | B3: 0.2727 | C3: 0.8 | D3: 0 | E3: 8 | F3: 32 | G3: 40 | H3: =IF(E3+F3=G3, "Ok", "Error") -> Ok | I3: =COUNTIF(H3:H611,"Error") -> 0
A4: 3 | B4: 0.2727 | C4: 0.8 | D4: 0 | E4: 5 | F4: 27 | G4: 32 | H4: =IF(E4+F4=G4, "Ok", "Error") -> Ok | I4: =COUNTIF(H4:H612,"Error") -> 0
A5: 4 | B5: 0.2879 | C5: 0.75 | D5: 0 | E5: 3 | F5: 10 | G5: 13 | H5: =IF(E5+F5=G5, "Ok", "Error") -> Ok | I5: =COUNTIF(H5:H613,"Error") -> 0
A6: 5 | B6: 0.2879 | C6: 0.75 | D6: 0 | E6: 0 | F6: 1 | G6: 1 | H6: =IF(E6+F6=G6, "Ok", "Error") -> Ok | I6: =COUNTIF(H6:H614,"Error") -> 0
A7: 6 | B7: 0.2576 | C7: 0.75 | D7: 0.0896 | E7: 0 | F7: 1 | G7: 1 | H7: =IF(E7+F7=G7, "Ok", "Error") -> Ok | I7: =COUNTIF(H7:H615,"Error") -> 0
A8: 7 | B8: 0.2727 | C8: 0.8 | D8: 0 | E8: 2 | F8: 0 | G8: 2 | H8: =IF(E8+F8=G8, "Ok", "Error") -> Ok | I8: =COUNTIF(H8:H616,"Error") -> 0
A9: 8 | B9: 0.2576 | C9: 0.86 | D9: 0 | E9: 1 | F9: 2 | G9: 3 | H9: =IF(E9+F9=G9, "Ok", "Error") -> Ok | I9: =COUNTIF(H9:H617,"Error") -> 0
A10: 9 | C10: 0.75 | D10: 0 | E10: 1 | F10: 7 | G10: 8 | H10: =IF(E10+F10=G10, "Ok", "Error") -> Ok | I10: =COUNTIF(H10:H618,"Error") -> 0
A11: 10 | B11: 0.3485 | C11: 0.76 | D11: 0 | E11: 8 | F11: 6 | G11: 14 | H11: =IF(E11+F11=G11, "Ok", "Error") -> Ok | I11: =COUNTIF(H11:H619,"Error") -> 0
A12: 11 | B12: 0.3939 | C12: 0.76 | D12: 0.2537 | E12: 12 | F12: 24 | G12: 36 | H12: =IF(E12+F12=G12, "Ok", "Error") -> Ok | I12: =COUNTIF(H12:H620,"Error") -> 0
A13: 12 | B13: 0.3333 | C13: 0.81 | D13: 0.2836 | E13: 26 | F13: 30 | G13: 56 | H13: =IF(E13+F13=G13, "Ok", "Error") -> Ok | I13: =COUNTIF(H13:H621,"Error") -> 0
A14: 13 | B14: 0.4242 | C14: 0.77 | D14: 0.2836 | E14: 29 | F14: 55 | G14: 84 | H14: =IF(E14+F14=G14, "Ok", "Error") -> Ok | I14: =COUNTIF(H14:H622,"Error") -> 0
A15: 14 | B15: 0.4545 | C15: 0.72 | D15: 0.2985 | E15: 47 | F15: 47 | G15: 94 | H15: =IF(E15+F15=G15, "Ok", "Error") -> Ok | I15: =COUNTIF(H15:H623,"Error") -> 0
A16: 15 | B16: 0.4545 | C16: 0.72 | D16: 0.2836 | E16: 35 | F16: 71 | G16: 106 | H16: =IF(E16+F16=G16, "Ok", "Error") -> Ok | I16: =COUNTIF(H16:H624,"Error") -> 0
A17: 16 | B17: 0.4394 | C17: 0.77 | D17: 0.2985 | E17: 40 | F17: 70 | G17: 110 | H17: =IF(E17+F17=G17, "Ok", "Error") -> Ok | I17: =COUNTIF(H17:H625,"Error") -> 0
A18: 17 | B18: 0.4242 | C18: 0.82 | D18: 0.2985 | E18: 41 | F18: 52 | G18: 93 | H18: =IF(E18+F18=G18, "Ok", "Error") -> Ok | I18: =COUNTIF(H18:H626,"Error") -> 0
A19: 18 | C19: 0.82 | D19: 0.2836 | E19: 15 | F19: 52 | G19: 67 | H19: =IF(E19+F19=G19, "Ok", "Error") -> Ok | I19: =COUNTIF(H19:H627,"Error") -> 0
A20: 19 | B20: 0.4242 | C20: 0.88 | D20: 0.2537 | E20: 9 | F20: 26 | G20: 35 | H20: =IF(E20+F20=G20, "Ok", "Error") -> Ok | I20: =COUNTIF(H20:H628,"Error") -> 0
A21: 20 | B21: 0.4242 | C21: 0.88 | D21: 0.2537 | E21: 6 | F21: 31 | G21: 37 | H21: =IF(E21+F21=G21, "Ok", "Error") -> Ok | I21: =COUNTIF(H21:H629,"Error") -> 0
A22: 21 | B22: 0.4091 | C22: 0.87 | D22: 0.2537 | E22: 11 | F22: 25 | G22: 36 | H22: =IF(E22+F22=G22, "Ok", "Error") -> Ok | I22: =COUNTIF(H22:H630,"Error") -> 0
A23: 22 | B23: 0.4091 | C23: 0.87 | D23: 0.194 | E23: 3 | F23: 31 | G23: 34 | H23: =IF(E23+F23=G23, "Ok", "Error") -> Ok | I23: =COUNTIF(H23:H631,"Error") -> 0
A24: 23 | B24: 0.4091 | C24: 0.94 | D24: 0.2239 | E24: 11 | F24: 17 | G24: 28 | H24: =IF(E24+F24=G24, "Ok", "Error") -> Ok | I24: =COUNTIF(H24:H632,"Error") -> 0
A25: 24 | C25: 0.88 | D25: 0.2985 | E25: 15 | F25: 24 | G25: 39 | H25: =IF(E25+F25=G25, "Ok", "Error") -> Ok | I25: =COUNTIF(H25:H633,"Error") -> 0
A26: 25 | B26: 0.4545 | C26: 0.88 | D26: 0.2985 | E26: 4 | F26: 13 | G26: 17 | H26: =IF(E26+F26=G26, "Ok", "Error") -> Ok | I26: =COUNTIF(H26:H634,"Error") -> 0
A27: 26 | B27: 0.4394 | C27: 0.94 | D27: 0.2537 | E27: 1 | F27: 16 | G27: 17 | H27: =IF(E27+F27=G27, "Ok", "Error") -> Ok | I27: =COUNTIF(H27:H635,"Error") -> 0
A28: 27 | B28: 0.4242 | C28: 1 | D28: 0.2836 | E28: 1 | F28: 8 | G28: 9 | H28: =IF(E28+F28=G28, "Ok", "Error") -> Ok | I28: =COUNTIF(H28:H636,"Error") -> 0
A29: 28 | B29: 0.4545 | C29: 0.94 | D29: 0.194 | E29: 2 | F29: 4 | G29: 6 | H29: =IF(E29+F29=G29, "Ok", "Error") -> Ok | I29: =COUNTIF(H29:H637,"Error") -> 0
A30: 29 | C30: 0.94 | D30: 0.194 | E30: 2 | F30: 1 | G30: 3 | H30: =IF(E30+F30=G30, "Ok", "Error") -> Ok | I30: =COUNTIF(H30:H638,"Error") -> 0
A31: 30 | B31: 0.4242 | C31: 0.77 | D31: 0.2985 | E31: 0 | F31: 2 | G31: 2 | H31: =IF(E31+F31=G31, "Ok", "Error") -> Ok | I31: =COUNTIF(H31:H639,"Error") -> 0
A32: 31 | B32: 0.4091 | C32: 0.76 | D32: 0.194 | E32: 0 | F32: 1 | G32: 1 | H32: =IF(E32+F32=G32, "Ok", "Error") -> Ok | I32: =COUNTIF(H32:H640,"Error") -> 0
A33: 32 | B33: 0.4091 | C33: 0.71 | D33: 0.2239 | E33: 0 | F33: 8 | G33: 8 | H33: =IF(E33+F33=G33, "Ok", "Error") -> Ok | I33: =COUNTIF(H33:H641,"Error") -> 0
A34: 33 | C34: 0.76 | D34: 0.2239 | E34: 1 | F34: 19 | G34: 20 | H34: =IF(E34+F34=G34, "Ok", "Error") -> Ok | I34: =COUNTIF(H34:H642,"Error") -> 0
A35: 34 | B35: 0.3485 | C35: 0.81 | D35: 0.2239 | E35: 7 | F35: 46 | G35: 53 | H35: =IF(E35+F35=G35, "Ok", "Error") -> Ok | I35: =COUNTIF(H35:H643,"Error") -> 0
A36: 35 | B36: 0.3333 | C36: 0.71 | D36: 0.2537 | E36: 16 | F36: 54 | G36: 70 | H36: =IF(E36+F36=G36, "Ok", "Error") -> Ok | I36: =COUNTIF(H36:H644,"Error") -> 0
A37: 36 | B37: 0.3333 | C37: 0.66 | D37: 0.2985 | E37: 20 | F37: 73 | G37: 93 | H37: =IF(E37+F37=G37, "Ok", "Error") -> Ok | I37: =COUNTIF(H37:H645,"Error") -> 0
A38: 37 | B38: 0.3485 | C38: 0.66 | D38: 0.1343 | E38: 11 | F38: 64 | G38: 75 | H38: =IF(E38+F38=G38, "Ok", "Error") -> Ok | I38: =COUNTIF(H38:H646,"Error") -> 0
A39: 38 | C39: 0.76 | D39: 0.194 | E39: 4 | F39: 55 | G39: 59 | H39: =IF(E39+F39=G39, "Ok", "Error") -> Ok | I39: =COUNTIF(H39:H647,"Error") -> 0
A40: 39 | B40: 0.3333 | C40: 0.81 | D40: 0.1642 | E40: 19 | F40: 55 | G40: 74 | H40: =IF(E40+F40=G40, "Ok", "Error") -> Ok | I40: =COUNTIF(H40:H648,"Error") -> 0
...

Sheet dataset_3
A1: instant | B1: dteday | C1: season | D1: yr | E1: mnth | F1: hr | G1: holiday | H1: weekday | I1: weathersit | J1: temp | K1: atemp | L1: hum | M1: windspeed | N1: casual | O1: registered | P1: cnt | R1: Duplicate Check | S1: Missing Check | T1: Demand Check | U1: Demand Errors
A2: 611 | B2: 40571 | C2: 1 | D2: 0 | E2: 1 | F2: 16 | G2: =FALSE() -> FALSE | H2: 5 | I2: 1 | J2: 0.22 | K2: 0.2727 | L2: 0.8 | M2: 0 | N2: 10 | O2: 70 | P2: 80 | R2: =COUNTIF($A$2:$A$391,A2) -> 1 | S2: =COUNTBLANK(A2:P2) -> 0 | T2: =IF(N2+O2=P2,"OK","ERROR") -> OK | U2: =COUNTIF(T2:T391,"ERROR") -> 0
A3: 612 | B3: 40571 | C3: 1 | D3: 0 | E3: 1 | F3: 17 | G3: =FALSE() -> FALSE | H3: 5 | I3: 1 | J3: 0.24 | K3: 0.2424 | L3: 0.75 | M3: 0.1343 | N3: 2 | O3: 147 | P3: 149 | R3: =COUNTIF($A$2:$A$391,A3) -> 1 | S3: =COUNTBLANK(A3:P3) -> 0 | T3: =IF(N3+O3=P3,"OK","ERROR") -> OK | U3: =COUNTIF(T3:T392,"ERROR") -> 0
A4: 613 | B4: 40571 | C4: 1 | D4: 0 | E4: 1 | F4: 18 | G4: =FALSE() -> FALSE | H4: 5 | I4: 1 | J4: 0.24 | K4: 0.2273 | L4: 0.75 | M4: 0.194 | N4: 2 | O4: 107 | P4: 109 | R4: =COUNTIF($A$2:$A$391,A4) -> 1 | S4: =COUNTBLANK(A4:P4) -> 0 | T4: =IF(N4+O4=P4,"OK","ERROR") -> OK | U4: =COUNTIF(T4:T393,"ERROR") -> 0
A5: 614 | B5: 40571 | C5: 1 | D5: 0 | E5: 1 | F5: 19 | G5: =FALSE() -> FALSE | H5: 5 | I5: 2 | J5: 0.24 | K5: 0.2424 | L5: 0.75 | M5: 0.1343 | N5: 5 | O5: 84 | P5: 89 | R5: =COUNTIF($A$2:$A$391,A5) -> 1 | S5: =COUNTBLANK(A5:P5) -> 0 | T5: =IF(N5+O5=P5,"OK","ERROR") -> OK | U5: =COUNTIF(T5:T394,"ERROR") -> 0
A6: 615 | B6: 40571 | C6: 1 | D6: 0 | E6: 1 | F6: 20 | G6: =FALSE() -> FALSE | H6: 5 | I6: 2 | J6: 0.24 | K6: 0.2273 | L6: 0.7 | M6: 0.194 | N6: 1 | O6: 61 | P6: 62 | R6: =COUNTIF($A$2:$A$391,A6) -> 1 | S6: =COUNTBLANK(A6:P6) -> 0 | T6: =IF(N6+O6=P6,"OK","ERROR") -> OK | U6: =COUNTIF(T6:T395,"ERROR") -> 0
A7: 616 | B7: 40571 | C7: 1 | D7: 0 | E7: 1 | F7: 21 | G7: =FALSE() -> FALSE | H7: 5 | I7: 2 | J7: 0.22 | K7: 0.2273 | L7: 0.75 | M7: 0.1343 | N7: 1 | O7: 57 | P7: 58 | R7: =COUNTIF($A$2:$A$391,A7) -> 1 | S7: =COUNTBLANK(A7:P7) -> 0 | T7: =IF(N7+O7=P7,"OK","ERROR") -> OK | U7: =COUNTIF(T7:T396,"ERROR") -> 0
A8: 617 | B8: 40571 | C8: 1 | D8: 0 | E8: 1 | F8: 22 | G8: =FALSE() -> FALSE | H8: 5 | I8: 1 | J8: 0.24 | K8: 0.2121 | L8: 0.65 | M8: 0.3582 | N8: 0 | O8: 26 | P8: 26 | R8: =COUNTIF($A$2:$A$391,A8) -> 1 | S8: =COUNTBLANK(A8:P8) -> 0 | T8: =IF(N8+O8=P8,"OK","ERROR") -> OK | U8: =COUNTIF(T8:T397,"ERROR") -> 0
A9: 618 | B9: 40571 | C9: 1 | D9: 0 | E9: 1 | F9: 23 | G9: =FALSE() -> FALSE | H9: 5 | I9: 1 | J9: 0.24 | K9: 0.2273 | L9: 0.6 | M9: 0.2239 | N9: 1 | O9: 22 | P9: 23 | R9: =COUNTIF($A$2:$A$391,A9) -> 1 | S9: =COUNTBLANK(A9:P9) -> 0 | T9: =IF(N9+O9=P9,"OK","ERROR") -> OK | U9: =COUNTIF(T9:T398,"ERROR") -> 0
A10: 619 | B10: 40572 | C10: 1 | D10: 0 | E10: 1 | F10: 0 | G10: =FALSE() -> FALSE | H10: 6 | I10: 1 | J10: 0.22 | K10: 0.197 | L10: 0.64 | M10: 0.3582 | N10: 2 | O10: 26 | P10: 28 | R10: =COUNTIF($A$2:$A$391,A10) -> 1 | S10: =COUNTBLANK(A10:P10) -> 0 | T10: =IF(N10+O10=P10,"OK","ERROR") -> OK | U10: =COUNTIF(T10:T399,"ERROR") -> 0
A11: 620 | B11: 40572 | C11: 1 | D11: 0 | E11: 1 | F11: 1 | G11: =FALSE() -> FALSE | H11: 6 | I11: 1 | J11: 0.22 | K11: 0.2273 | L11: 0.64 | M11: 0.194 | N11: 0 | O11: 20 | P11: 20 | R11: =COUNTIF($A$2:$A$391,A11) -> 1 | S11: =COUNTBLANK(A11:P11) -> 0 | T11: =IF(N11+O11=P11,"OK","ERROR") -> OK | U11: =COUNTIF(T11:T400,"ERROR") -> 0
A12: 621 | B12: 40572 | C12: 1 | D12: 0 | E12: 1 | F12: 2 | G12: =FALSE() -> FALSE | H12: 6 | I12: 1 | J12: 0.22 | K12: 0.2273 | L12: 0.64 | M12: 0.1642 | N12: 0 | O12: 15 | P12: 15 | R12: =COUNTIF($A$2:$A$391,A12) -> 1 | S12: =COUNTBLANK(A12:P12) -> 0 | T12: =IF(N12+O12=P12,"OK","ERROR") -> OK | U12: =COUNTIF(T12:T401,"ERROR") -> 0
A13: 622 | B13: 40572 | C13: 1 | D13: 0 | E13: 1 | F13: 3 | G13: =FALSE() -> FALSE | H13: 6 | I13: 1 | J13: 0.2 | K13: 0.2121 | L13: 0.64 | M13: 0.1343 | N13: 3 | O13: 5 | P13: 8 | R13: =COUNTIF($A$2:$A$391,A13) -> 1 | S13: =COUNTBLANK(A13:P13) -> 0 | T13: =IF(N13+O13=P13,"OK","ERROR") -> OK | U13: =COUNTIF(T13:T402,"ERROR") -> 0
... A391: 1000 | B391: 40588 | C391: 1 | D391: 0 | E391: 2 | F391: 7 | G391: =FALSE() -> FALSE | H391: 1 | I391: 1 | J391: 0.34 | K391: 0.303 | L391: 0.46 | M391: 0.2985 | N391: 2 | O391: 96 | P391: 98 | R391: =COUNTIF($A$2:$A$391,A391) -> 1 | S391: =COUNTBLANK(A391:P391) -> 0 | T391: =IF(N391+O391=P391,"OK","ERROR") -> OK | U391: =COUNTIF(T391:T780,"ERROR") -> 0

Sheet dataset_A
A1: instant | B1: dteday | C1: season | D1: yr | E1: mnth | F1: hr | G1: holiday | H1: weekday | I1: weathersit | J1: temp | K1: atemp | L1: hum | M1: windspeed | N1: casual | O1: registered | P1: cnt | R1: Merege_Check | S1: Merge_Errors | T1: Demand Check | U1: Duplicate Check
A2: =dataset_1!A441 -> 440 | B2: =dataset_1!B441 -> 40563 | C2: =dataset_1!C441 -> 1 | D2: =dataset_1!D441 -> 0 | E2: =dataset_1!E441 -> 1 | F2: =dataset_1!F441 -> 8 | G2: =dataset_1!G441 -> FALSE | H2: =dataset_1!H441 -> 4 | ... J2: =dataset_1!J441 -> 0.22 | K2: =VLOOKUP(A2,dataset_2!$A$2:$G$611,2,0) -> 0.2121 | L2: =VLOOKUP(A2,dataset_2!$A$2:$G$611,3,0) -> 0.55 | M2: =VLOOKUP(A2,dataset_2!$A$2:$G$611,4,0) -> 0.2836 | N2: =VLOOKUP(A2,dataset_2!$A$2:$G$611,5,0) -> 2 | O2: =VLOOKUP(A2,dataset_2!$A$2:$G$611,6,0) -> 247 | P2: =VLOOKUP(A2,dataset_2!$A$2:$G$611,7,0) -> 249 | R2: =IF(COUNTA(A2:P2)=16,"OK","CHECK") -> OK | S2: =COUNTIF(R2:R610,"CHECK") -> 5 | T2: =IF(N2+O2=P2,"OK","Error") -> OK | U2: =COUNTIF($A$2:$A$1001,A2) -> 1
A3: 862 | B3: 40582 | C3: 1 | D3: 0 | E3: 2 | F3: 8 | G3: =FALSE() -> FALSE | H3: 2 | I3: 1 | J3: 0.24 | K3: 0.197 | L3: 0.56 | M3: 0.4925 | N3: 7 | O3: 236 | P3: 243 | R3: =IF(COUNTA(A3:P3)=16,"OK","CHECK") -> OK | S3: =COUNTIF(R3:R611,"CHECK") -> 5 | T3: =IF(N3+O3=P3,"OK","Error") -> OK | U3: =COUNTIF($A$2:$A$1001,A3) -> 1
A4: =dataset_1!A557 -> 556 | B4: =dataset_1!B557 -> 40568 | C4: =dataset_1!C557 -> 1 | D4: =dataset_1!D557 -> 0 | E4: =dataset_1!E557 -> 1 | F4: =dataset_1!F557 -> 8 | G4: =dataset_1!G557 -> FALSE | H4: =dataset_1!H557 -> 2 | ... J4: =dataset_1!J557 -> 0.16 | K4: =VLOOKUP(A4,dataset_2!$A$2:$G$611,2,0) -> 0.1818 | L4: =VLOOKUP(A4,dataset_2!$A$2:$G$611,3,0) -> 0.74 | M4: =VLOOKUP(A4,dataset_2!$A$2:$G$611,4,0) -> 0.1343 | N4: =VLOOKUP(A4,dataset_2!$A$2:$G$611,5,0) -> 5 | O4: =VLOOKUP(A4,dataset_2!$A$2:$G$611,6,0) -> 233 | P4: =VLOOKUP(A4,dataset_2!$A$2:$G$611,7,0) -> 238 | R4: =IF(COUNTA(A4:P4)=16,"OK","CHECK") -> OK | S4: =COUNTIF(R4:R612,"CHECK") -> 5 | T4: =IF(N4+O4=P4,"OK","Error") -> OK | U4: =COUNTIF($A$2:$A$1001,A4) -> 1
A5: 838 | B5: 40581 | C5: 1 | D5: 0 | E5: 2 | F5: 8 | G5: =FALSE() -> FALSE | H5: 1 | I5: 2 | J5: 0.16 | K5: 0.2273 | L5: 1 | M5: 0 | N5: 7 | O5: 223 | P5: 230 | R5: =IF(COUNTA(A5:P5)=16,"OK","CHECK") -> OK | S5: =COUNTIF(R5:R613,"CHECK") -> 5 | T5: =IF(N5+O5=P5,"OK","Error") -> OK | U5: =COUNTIF($A$2:$A$1001,A5) -> 1
A6: =dataset_1!A567 -> 566 | B6: =dataset_1!B567 -> 40568 | C6: =dataset_1!C567 -> 1 | D6: =dataset_1!D567 -> 0 | E6: =dataset_1!E567 -> 1 | F6: =dataset_1!F567 -> 18 | G6: =dataset_1!G567 -> FALSE | H6: =dataset_1!H567 -> 2 | ... J6: =dataset_1!J567 -> 0.3 | K6: =VLOOKUP(A6,dataset_2!$A$2:$G$611,2,0) -> 0.3182 | L6: =VLOOKUP(A6,dataset_2!$A$2:$G$611,3,0) -> 0.49 | M6: =VLOOKUP(A6,dataset_2!$A$2:$G$611,4,0) -> 0.0896 | N6: =VLOOKUP(A6,dataset_2!$A$2:$G$611,5,0) -> 7 | O6: =VLOOKUP(A6,dataset_2!$A$2:$G$611,6,0) -> 218 | P6: =VLOOKUP(A6,dataset_2!$A$2:$G$611,7,0) -> 225 | R6: =IF(COUNTA(A6:P6)=16,"OK","CHECK") -> OK | S6: =COUNTIF(R6:R614,"CHECK") -> 5 | T6: =IF(N6+O6=P6,"OK","Error") -> OK | U6: =COUNTIF($A$2:$A$1001,A6) -> 1
A7: =dataset_1!A566 -> 565 | B7: =dataset_1!B566 -> 40568 | C7: =dataset_1!C566 -> 1 | D7: =dataset_1!D566 -> 0 | E7: =dataset_1!E566 -> 1 | F7: =dataset_1!F566 -> 17 | G7: =dataset_1!G566 -> FALSE | H7: =dataset_1!H566 -> 2 | ... J7: =dataset_1!J566 -> 0.3 | K7: =VLOOKUP(A7,dataset_2!$A$2:$G$611,2,0) -> 0.3333 | L7: =VLOOKUP(A7,dataset_2!$A$2:$G$611,3,0) -> 0.45 | M7: =VLOOKUP(A7,dataset_2!$A$2:$G$611,4,0) -> 0 | N7: =VLOOKUP(A7,dataset_2!$A$2:$G$611,5,0) -> 14 | O7: =VLOOKUP(A7,dataset_2!$A$2:$G$611,6,0) -> 208 | P7: =VLOOKUP(A7,dataset_2!$A$2:$G$611,7,0) -> 222 | R7: =IF(COUNTA(A7:P7)=16,"OK","CHECK") -> OK | S7: =COUNTIF(R7:R615,"CHECK") -> 5 | T7: =IF(N7+O7=P7,"OK","Error") -> OK | U7: =COUNTIF($A$2:$A$1001,A7) -> 1
A8: 766 | B8: 40578 | C8: 1 | D8: 0 | E8: 2 | F8: 8 | G8: =FALSE() -> FALSE | H8: 5 | I8: 1 | J8: 0.14 | K8: 0.1515 | L8: 0.74 | M8: 0.1343 | N8: 3 | O8: 217 | P8: 220 | R8: =IF(COUNTA(A8:P8)=16,"OK","CHECK") -> OK | S8: =COUNTIF(R8:R616,"CHECK") -> 5 | T8: =IF(N8+O8=P8,"OK","Error") -> OK | U8: =COUNTIF($A$2:$A$1001,A8) -> 1
A9: =dataset_1!A124 -> 123 | B9: =dataset_1!B124 -> 40549 | C9: =dataset_1!C124 -> 1 | D9: =dataset_1!D124 -> 0 | E9: =dataset_1!E124 -> 1 | F9: =dataset_1!F124 -> 8 | G9: =dataset_1!G124 -> FALSE | H9: =dataset_1!H124 -> 4 | ... J9: =dataset_1!J124 -> 0.16 | K9: =VLOOKUP(A9,dataset_2!$A$2:$G$611,2,0) -> 0.2273 | L9: =VLOOKUP(A9,dataset_2!$A$2:$G$611,3,0) -> 0.59 | M9: =VLOOKUP(A9,dataset_2!$A$2:$G$611,4,0) -> 0 | N9: =VLOOKUP(A9,dataset_2!$A$2:$G$611,5,0) -> 3 | O9: =VLOOKUP(A9,dataset_2!$A$2:$G$611,6,0) -> 216 | P9: =VLOOKUP(A9,dataset_2!$A$2:$G$611,7,0) -> 219 | R9: =IF(COUNTA(A9:P9)=16,"OK","CHECK") -> OK | S9: =COUNTIF(R9:R617,"CHECK") -> 5 | T9: =IF(N9+O9=P9,"OK","Error") -> OK | U9: =COUNTIF($A$2:$A$1001,A9) -> 1
A10: =dataset_1!A241 -> 240 | B10: =dataset_1!B241 -> 40554 | C10: =dataset_1!C241 -> 1 | D10: =dataset_1!D241 -> 0 | E10: =dataset_1!E241 -> 1 | F10: =dataset_1!F241 -> 8 | G10: =dataset_1!G241 -> FALSE | H10: =dataset_1!H241 -> 2 | ... J10: =dataset_1!J241 -> 0.18 | K10: =VLOOKUP(A10,dataset_2!$A$2:$G$611,2,0) -> 0.2121 | L10: =VLOOKUP(A10,dataset_2!$A$2:$G$611,3,0) -> 0.51 | M10: =VLOOKUP(A10,dataset_2!$A$2:$G$611,4,0) -> 0.0896 | N10: =VLOOKUP(A10,dataset_2!$A$2:$G$611,5,0) -> 3 | O10: =VLOOKUP(A10,dataset_2!$A$2:$G$611,6,0) -> 214 | P10: =VLOOKUP(A10,dataset_2!$A$2:$G$611,7,0) -> 217 | R10: =IF(COUNTA(A10:P10)=16,"OK","CHECK") -> OK | S10: =COUNTIF(R10:R618,"CHECK") -> 5 | T10: =IF(N10+O10=P10,"OK","Error") -> OK | U10: =COUNTIF($A$2:$A$1001,A10) -> 1
A11: =dataset_1!A465 -> 464 | B11: =dataset_1!B465 -> 40564 | C11: =dataset_1!C465 -> 1 | D11: =dataset_1!D465 -> 0 | E11: =dataset_1!E465 -> 1 | F11: =dataset_1!F465 -> 8 | G11: =dataset_1!G465 -> FALSE | H11: =dataset_1!H465 -> 5 | ... J11: =dataset_1!J465 -> 0.2 | K11: =VLOOKUP(A11,dataset_2!$A$2:$G$611,2,0) -> 0.1818 | L11: =VLOOKUP(A11,dataset_2!$A$2:$G$611,3,0) -> 0.47 | M11: =VLOOKUP(A11,dataset_2!$A$2:$G$611,4,0) -> 0.3284 | N11: =VLOOKUP(A11,dataset_2!$A$2:$G$611,5,0) -> 7 | O11: =VLOOKUP(A11,dataset_2!$A$2:$G$611,6,0) -> 210 | P11: =VLOOKUP(A11,dataset_2!$A$2:$G$611,7,0) -> 217 | R11: =IF(COUNTA(A11:P11)=16,"OK","CHECK") -> OK | S11: =COUNTIF(R11:R619,"CHECK") -> 5 | T11: =IF(N11+O11=P11,"OK","Error") -> OK | U11: =COUNTIF($A$2:$A$1001,A11) -> 1
A12: 847 | B12: 40581 | C12: 1 | D12: 0 | E12: 2 | F12: 17 | G12: =FALSE() -> FALSE | H12: 1 | I12: 2 | J12: 0.32 | K12: 0.3182 | L12: 0.7 | M12: 0.1642 | N12: 9 | O12: 207 | P12: 216 | R12: =IF(COUNTA(A12:P12)=16,"OK","CHECK") -> OK | S12: =COUNTIF(R12:R620,"CHECK") -> 5 | T12: =IF(N12+O12=P12,"OK","Error") -> OK | U12: =COUNTIF($A$2:$A$1001,A12) -> 1
A13: 930 | B13: 40585 | C13: 1 | D13: 0 | E13: 2 | F13: 8 | G13: =FALSE() -> FALSE | H13: 5 | I13: 1 | J13: 0.1 | K13: 0.1212 | L13: 0.74 | M13: 0.1642 | N13: 4 | O13: 212 | P13: 216 | R13: =IF(COUNTA(A13:P13)=16,"OK","CHECK") -> OK | S13: =COUNTIF(R13:R621,"CHECK") -> 5 | T13: =IF(N13+O13=P13,"OK","Error") -> OK | U13: =COUNTIF($A$2:$A$1001,A13) -> 1
A14: =dataset_1!A450 -> 449 | B14: =dataset_1!B450 -> 40563 | C14: =dataset_1!C450 -> 1 | D14: =dataset_1!D450 -> 0 | E14: =dataset_1!E450 -> 1 | F14: =dataset_1!F450 -> 17 | G14: =dataset_1!G450 -> FALSE | H14: =dataset_1!H450 -> 4 | ... J14: =dataset_1!J450 -> 0.3 | K14: =VLOOKUP(A14,dataset_2!$A$2:$G$611,2,0) -> 0.3182 | L14: =VLOOKUP(A14,dataset_2!$A$2:$G$611,3,0) -> 0.49 | M14: =VLOOKUP(A14,dataset_2!$A$2:$G$611,4,0) -> 0.1045 | N14: =VLOOKUP(A14,dataset_2!$A$2:$G$611,5,0) -> 8 | O14: =VLOOKUP(A14,dataset_2!$A$2:$G$611,6,0) -> 207 | P14: =VLOOKUP(A14,dataset_2!$A$2:$G$611,7,0) -> 215 | R14: =IF(COUNTA(A14:P14)=16,"OK","CHECK") -> OK | S14: =COUNTIF(R14:R622,"CHECK") -> 5 | T14: =IF(N14+O14=P14,"OK","Error") -> OK | U14: =COUNTIF($A$2:$A$1001,A14) -> 1
A15: =dataset_1!A87 -> 86 | B15: =dataset_1!B87 -> 40547 | C15: =dataset_1!C87 -> 1 | D15: =dataset_1!D87 -> 0 | E15: =dataset_1!E87 -> 1 | F15: =dataset_1!F87 -> 17 | G15: =dataset_1!G87 -> FALSE | H15: =dataset_1!H87 -> 2 | ... J15: =dataset_1!J87 -> 0.28 | K15: =VLOOKUP(A15,dataset_2!$A$2:$G$611,2,0) -> 0.2727 | L15: =VLOOKUP(A15,dataset_2!$A$2:$G$611,3,0) -> 0.48 | M15: =VLOOKUP(A15,dataset_2!$A$2:$G$611,4,0) -> 0.2239 | N15: =VLOOKUP(A15,dataset_2!$A$2:$G$611,5,0) -> 10 | O15: =VLOOKUP(A15,dataset_2!$A$2:$G$611,6,0) -> 202 | P15: =VLOOKUP(A15,dataset_2!$A$2:$G$611,7,0) -> 212 | R15: =IF(COUNTA(A15:P15)=16,"OK","CHECK") -> OK | S15: =COUNTIF(R15:R623,"CHECK") -> 5 | T15: =IF(N15+O15=P15,"OK","Error") -> OK | U15: =COUNTIF($A$2:$A$1001,A15) -> 1
A16: 939 | B16: 40585 | C16: 1 | D16: 0 | E16: 2 | F16: 17 | G16: =FALSE() -> FALSE | H16: 5 | I16: 1 | J16: 0.3 | K16: 0.3333 | L16: 0.24 | M16: 0 | N16: 18 | O16: 193 | P16: 211 | R16: =IF(COUNTA(A16:P16)=16,"OK","CHECK") -> OK | S16: =COUNTIF(R16:R624,"CHECK") -> 5 | T16: =IF(N16+O16=P16,"OK","Error") -> OK | U16: =COUNTIF($A$2:$A$1001,A16) -> 1
A17: =dataset_1!A147 -> 146 | B17: =dataset_1!B147 -> 40550 | C17: =dataset_1!C147 -> 1 | D17: =dataset_1!D147 -> 0 | E17: =dataset_1!E147 -> 1 | F17: =dataset_1!F147 -> 8 | G17: =dataset_1!G147 -> FALSE | H17: =dataset_1!H147 -> 5 | ... J17: =dataset_1!J147 -> 0.2 | K17: =VLOOKUP(A17,dataset_2!$A$2:$G$611,2,0) -> 0.197 | L17: =VLOOKUP(A17,dataset_2!$A$2:$G$611,3,0) -> 0.51 | M17: =VLOOKUP(A17,dataset_2!$A$2:$G$611,4,0) -> 0.2537 | N17: =VLOOKUP(A17,dataset_2!$A$2:$G$611,5,0) -> 20 | O17: =VLOOKUP(A17,dataset_2!$A$2:$G$611,6,0) -> 190 | P17: =VLOOKUP(A17,dataset_2!$A$2:$G$611,7,0) -> 210 | R17: =IF(COUNTA(A17:P17)=16,"OK","CHECK") -> OK | S17: =COUNTIF(R17:R625,"CHECK") -> 5 | T17: =IF(N17+O17=P17,"OK","Error") -> OK | U17: =COUNTIF($A$2:$A$1001,A17) -> 1
A18: 775 | B18: 40578 | C18: 1 | D18: 0 | E18: 2 | F18: 17 | G18: =FALSE() -> FALSE | H18: 5 | I18: 2 | J18: 0.26 | K18: 0.2727 | L18: 0.56 | M18: 0.1343 | N18: 10 | O18: 195 | P18: 205 | R18: =IF(COUNTA(A18:P18)=16,"OK","CHECK") -> OK | S18: =COUNTIF(R18:R626,"CHECK") -> 5 | T18: =IF(N18+O18=P18,"OK","Error") -> OK | U18: =COUNTIF($A$2:$A$1001,A18) -> 1
A19: =dataset_1!A287 -> 286 | B19: =dataset_1!B287 -> 40556 | C19: =dataset_1!C287 -> 1 | D19: =dataset_1!D287 -> 0 | E19: =dataset_1!E287 -> 1 | F19: =dataset_1!F287 -> 8 | G19: =dataset_1!G287 -> FALSE | H19: =dataset_1!H287 -> 4 | ... J19: =dataset_1!J287 -> 0.14 | K19: =VLOOKUP(A19,dataset_2!$A$2:$G$611,2,0) -> 0.1364 | L19: =VLOOKUP(A19,dataset_2!$A$2:$G$611,3,0) -> 0.5 | M19: =VLOOKUP(A19,dataset_2!$A$2:$G$611,4,0) -> 0.194 | N19: =VLOOKUP(A19,dataset_2!$A$2:$G$611,5,0) -> 5 | O19: =VLOOKUP(A19,dataset_2!$A$2:$G$611,6,0) -> 197 | P19: =VLOOKUP(A19,dataset_2!$A$2:$G$611,7,0) -> 202 | R19: =IF(COUNTA(A19:P19)=16,"OK","CHECK") -> OK | S19: =COUNTIF(R19:R627,"CHECK") -> 5 | T19: =IF(N19+O19=P19,"OK","Error") -> OK | U19: =COUNTIF($A$2:$A$1001,A19) -> 1
A20: 885 | B20: 40583 | C20: 1 | D20: 0 | E20: 2 | F20: 8 | G20: =FALSE() -> FALSE | H20: 3 | I20: 1 | J20: 0.1 | K20: 0.1364 | L20: 0.42 | M20: 0 | N20: 1 | O20: 198 | P20: 199 | R20: =IF(COUNTA(A20:P20)=16,"OK","CHECK") -> OK | S20: =COUNTIF(R20:R628,"CHECK") -> 5 | T20: =IF(N20+O20=P20,"OK","Error") -> OK | U20: =COUNTIF($A$2:$A$1001,A20) -> 1
A21: =dataset_1!A417 -> 416 | B21: =dataset_1!B417 -> 40562 | C21: =dataset_1!C417 -> 1 | D21: =dataset_1!D417 -> 0 | E21: =dataset_1!E417 -> 1 | F21: =dataset_1!F417 -> 8 | G21: =dataset_1!G417 -> FALSE | H21: =dataset_1!H417 -> 3 | ... J21: =dataset_1!J417 -> 0.24 | K21: =VLOOKUP(A21,dataset_2!$A$2:$G$611,2,0) -> 0.2576 | L21: =VLOOKUP(A21,dataset_2!$A$2:$G$611,3,0) -> 0.93 | M21: =VLOOKUP(A21,dataset_2!$A$2:$G$611,4,0) -> 0.1045 | N21: =VLOOKUP(A21,dataset_2!$A$2:$G$611,5,0) -> 1 | O21: =VLOOKUP(A21,dataset_2!$A$2:$G$611,6,0) -> 196 | P21: =VLOOKUP(A21,dataset_2!$A$2:$G$611,7,0) -> 197 | R21: =IF(COUNTA(A21:P21)=16,"OK","CHECK") -> OK | S21: =COUNTIF(R21:R629,"CHECK") -> 5 | T21: =IF(N21+O21=P21,"OK","Error") -> OK | U21: =COUNTIF($A$2:$A$1001,A21) -> 1
A22: =dataset_1!A426 -> 425 | B22: =dataset_1!B426 -> 40562 | C22: =dataset_1!C426 -> 1 | D22: =dataset_1!D426 -> 0 | E22: =dataset_1!E426 -> 1 | F22: =dataset_1!F426 -> 17 | G22: =dataset_1!G426 -> FALSE | H22: =dataset_1!H426 -> 3 | ... J22: =dataset_1!J426 -> 0.36 | K22: =VLOOKUP(A22,dataset_2!$A$2:$G$611,2,0) -> 0.3333 | L22: =VLOOKUP(A22,dataset_2!$A$2:$G$611,3,0) -> 0.57 | M22: =VLOOKUP(A22,dataset_2!$A$2:$G$611,4,0) -> 0.3284 | N22: =VLOOKUP(A22,dataset_2!$A$2:$G$611,5,0) -> 7 | O22: =VLOOKUP(A22,dataset_2!$A$2:$G$611,6,0) -> 190 | P22: =VLOOKUP(A22,dataset_2!$A$2:$G$611,7,0) -> 197 | R22: =IF(COUNTA(A22:P22)=16,"OK","CHECK") -> OK | S22: =COUNTIF(R22:R630,"CHECK") -> 5 | T22: =IF(N22+O22=P22,"OK","Error") -> OK | U22: =COUNTIF($A$2:$A$1001,A22) -> 1
A23: =dataset_1!A101 -> 100 | B23: =dataset_1!B101 -> 40548 | C23: =dataset_1!C101 -> 1 | D23: =dataset_1!D101 -> 0 | E23: =dataset_1!E101 -> 1 | F23: =dataset_1!F101 -> 8 | G23: =dataset_1!G101 -> FALSE | H23: =dataset_1!H101 -> 3 | ... J23: =dataset_1!J101 -> 0.2 | K23: =VLOOKUP(A23,dataset_2!$A$2:$G$611,2,0) -> 0.1818 | L23: =VLOOKUP(A23,dataset_2!$A$2:$G$611,3,0) -> 0.4 | M23: =VLOOKUP(A23,dataset_2!$A$2:$G$611,4,0) -> 0.2985 | N23: =VLOOKUP(A23,dataset_2!$A$2:$G$611,5,0) -> 3 | O23: =VLOOKUP(A23,dataset_2!$A$2:$G$611,6,0) -> 192 | P23: =VLOOKUP(A23,dataset_2!$A$2:$G$611,7,0) -> 195 | R23: =IF(COUNTA(A23:P23)=16,"OK","CHECK") -> OK | S23: =COUNTIF(R23:R631,"CHECK") -> 5 | T23: =IF(N23+O23=P23,"OK","Error") -> OK | U23: =COUNTIF($A$2:$A$1001,A23) -> 1
A24: =dataset_1!A110 -> 109 | B24: =dataset_1!B110 -> 40548 | C24: =dataset_1!C110 -> 1 | D24: =dataset_1!D110 -> 0 | E24: =dataset_1!E110 -> 1 | F24: =dataset_1!F110 -> 17 | G24: =dataset_1!G110 -> FALSE | H24: =dataset_1!H110 -> 3 | ... J24: =dataset_1!J110 -> 0.24 | K24: =VLOOKUP(A24,dataset_2!$A$2:$G$611,2,0) -> 0.2273 | L24: =VLOOKUP(A24,dataset_2!$A$2:$G$611,3,0) -> 0.38 | M24: =VLOOKUP(A24,dataset_2!$A$2:$G$611,4,0) -> 0.194 | N24: =VLOOKUP(A24,dataset_2!$A$2:$G$611,5,0) -> 4 | O24: =VLOOKUP(A24,dataset_2!$A$2:$G$611,6,0) -> 186 | P24: =VLOOKUP(A24,dataset_2!$A$2:$G$611,7,0) -> 190 | R24: =IF(COUNTA(A24:P24)=16,"OK","CHECK") -> OK | S24: =COUNTIF(R24:R632,"CHECK") -> 5 | T24: =IF(N24+O24=P24,"OK","Error") -> OK | U24: =COUNTIF($A$2:$A$1001,A24) -> 1
A25: 729 | B25: 40576 | C25: 1 | D25: 0 | E25: 2 | F25: 17 | G25: =FALSE() -> FALSE | H25: 3 | I25: 1 | J25: 0.36 | K25: 0.3182 | L25: 0.53 | M25: 0.5224 | N25: 7 | O25: 183 | P25: 190 | R25: =IF(COUNTA(A25:P25)=16,"OK","CHECK") -> OK | S25: =COUNTIF(R25:R633,"CHECK") -> 5 | T25: =IF(N25+O25=P25,"OK","Error") -> OK | U25: =COUNTIF($A$2:$A$1001,A25) -> 1
A26: =dataset_1!A219 -> 218 | B26: =dataset_1!B219 -> 40553 | C26: =dataset_1!C219 -> 1 | D26: =dataset_1!D219 -> 0 | E26: =dataset_1!E219 -> 1 | F26: =dataset_1!F219 -> 8 | G26: =dataset_1!G219 -> FALSE | H26: =dataset_1!H219 -> 1 | ... J26: =dataset_1!J219 -> 0.12 | K26: =VLOOKUP(A26,dataset_2!$A$2:$G$611,2,0) -> 0.1212 | L26: =VLOOKUP(A26,dataset_2!$A$2:$G$611,3,0) -> 0.5 | M26: =VLOOKUP(A26,dataset_2!$A$2:$G$611,4,0) -> 0.2836 | N26: =VLOOKUP(A26,dataset_2!$A$2:$G$611,5,0) -> 4 | O26: =VLOOKUP(A26,dataset_2!$A$2:$G$611,6,0) -> 184 | P26: =VLOOKUP(A26,dataset_2!$A$2:$G$611,7,0) -> 188 | R26: =IF(COUNTA(A26:P26)=16,"OK","CHECK") -> OK | S26: =COUNTIF(R26:R634,"CHECK") -> 5 | T26: =IF(N26+O26=P26,"OK","Error") -> OK | U26: =COUNTIF($A$2:$A$1001,A26) -> 1
A27: 743 | B27: 40577 | C27: 1 | D27: 0 | E27: 2 | F27: 8 | G27: =FALSE() -> FALSE | H27: 4 | I27: 1 | J27: 0.14 | K27: 0.1212 | L27: 0.5 | M27: 0.3582 | N27: 4 | O27: 184 | P27: 188 | R27: =IF(COUNTA(A27:P27)=16,"OK","CHECK") -> OK | S27: =COUNTIF(R27:R635,"CHECK") -> 5 | T27: =IF(N27+O27=P27,"OK","Error") -> OK | U27: =COUNTIF($A$2:$A$1001,A27) -> 1
A28: =dataset_1!A156 -> 155 | B28: =dataset_1!B156 -> 40550 | C28: =dataset_1!C156 -> 1 | D28: =dataset_1!D156 -> 0 | E28: =dataset_1!E156 -> 1 | F28: =dataset_1!F156 -> 17 | G28: =dataset_1!G156 -> FALSE | H28: =dataset_1!H156 -> 5 | ... J28: =dataset_1!J156 -> 0.2 | K28: =VLOOKUP(A28,dataset_2!$A$2:$G$611,2,0) -> 0.2576 | L28: =VLOOKUP(A28,dataset_2!$A$2:$G$611,3,0) -> 0.37 | M28: =VLOOKUP(A28,dataset_2!$A$2:$G$611,4,0) -> 0 | N28: =VLOOKUP(A28,dataset_2!$A$2:$G$611,5,0) -> 9 | O28: =VLOOKUP(A28,dataset_2!$A$2:$G$611,6,0) -> 178 | P28: =VLOOKUP(A28,dataset_2!$A$2:$G$611,7,0) -> 187 | R28: =IF(COUNTA(A28:P28)=16,"OK","CHECK") -> OK | S28: =COUNTIF(R28:R636,"CHECK") -> 5 | T28: =IF(N28+O28=P28,"OK","Error") -> OK | U28: =COUNTIF($A$2:$A$1001,A28) -> 1
A29: =dataset_1!A451 -> 450 | B29: =dataset_1!B451 -> 40563 | C29: =dataset_1!C451 -> 1 | D29: =dataset_1!D451 -> 0 | E29: =dataset_1!E451 -> 1 | F29: =dataset_1!F451 -> 18 | G29: =dataset_1!G451 -> FALSE | H29: =dataset_1!H451 -> 4 | ... J29: =dataset_1!J451 -> 0.26 | K29: =VLOOKUP(A29,dataset_2!$A$2:$G$611,2,0) -> 0.2576 | L29: =VLOOKUP(A29,dataset_2!$A$2:$G$611,3,0) -> 0.56 | M29: =VLOOKUP(A29,dataset_2!$A$2:$G$611,4,0) -> 0.194 | N29: =VLOOKUP(A29,dataset_2!$A$2:$G$611,5,0) -> 1 | O29: =VLOOKUP(A29,dataset_2!$A$2:$G$611,6,0) -> 184 | P29: =VLOOKUP(A29,dataset_2!$A$2:$G$611,7,0) -> 185 | R29: =IF(COUNTA(A29:P29)=16,"OK","CHECK") -> OK | S29: =COUNTIF(R29:R637,"CHECK") -> 5 | T29: =IF(N29+O29=P29,"OK","Error") -> OK | U29: =COUNTIF($A$2:$A$1001,A29) -> 1
A30: 673 | B30: 40574 | C30: 1 | D30: 0 | E30: 1 | F30: 8 | G30: =FALSE() -> FALSE | H30: 1 | I30: 2 | J30: 0.16 | K30: 0.1364 | L30: 0.59 | M30: 0.2836 | N30: 3 | O30: 182 | P30: 185 | R30: =IF(COUNTA(A30:P30)=16,"OK","CHECK") -> OK | S30: =COUNTIF(R30:R638,"CHECK") -> 5 | T30: =IF(N30+O30=P30,"OK","Error") -> OK | U30: =COUNTIF($A$2:$A$1001,A30) -> 1
A31: =dataset_1!A543 -> 542 | B31: =dataset_1!B543 -> 40567 | C31: =dataset_1!C543 -> 1 | D31: =dataset_1!D543 -> 0 | E31: =dataset_1!E543 -> 1 | F31: =dataset_1!F543 -> 17 | G31: =dataset_1!G543 -> FALSE | H31: =dataset_1!H543 -> 1 | ... J31: =dataset_1!J543 -> 0.14 | K31: =VLOOKUP(A31,dataset_2!$A$2:$G$611,2,0) -> 0.1212 | L31: =VLOOKUP(A31,dataset_2!$A$2:$G$611,3,0) -> 0.5 | M31: =VLOOKUP(A31,dataset_2!$A$2:$G$611,4,0) -> 0.2537 | N31: =VLOOKUP(A31,dataset_2!$A$2:$G$611,5,0) -> 6 | O31: =VLOOKUP(A31,dataset_2!$A$2:$G$611,6,0) -> 178 | P31: =VLOOKUP(A31,dataset_2!$A$2:$G$611,7,0) -> 184 | R31: =IF(COUNTA(A31:P31)=16,"OK","CHECK") -> OK | S31: =COUNTIF(R31:R639,"CHECK") -> 5 | T31: =IF(N31+O31=P31,"OK","Error") -> OK | U31: =COUNTIF($A$2:$A$1001,A31) -> 1
A32: =dataset_1!A88 -> 87 | B32: =dataset_1!B88 -> 40547 | C32: =dataset_1!C88 -> 1 | D32: =dataset_1!D88 -> 0 | E32: =dataset_1!E88 -> 1 | F32: =dataset_1!F88 -> 18 | G32: =dataset_1!G88 -> FALSE | H32: =dataset_1!H88 -> 2 | ... J32: =dataset_1!J88 -> 0.26 | K32: =VLOOKUP(A32,dataset_2!$A$2:$G$611,2,0) -> 0.2576 | L32: =VLOOKUP(A32,dataset_2!$A$2:$G$611,3,0) -> 0.48 | M32: =VLOOKUP(A32,dataset_2!$A$2:$G$611,4,0) -> 0.194 | N32: =VLOOKUP(A32,dataset_2!$A$2:$G$611,5,0) -> 3 | O32: =VLOOKUP(A32,dataset_2!$A$2:$G$611,6,0) -> 179 | P32: =VLOOKUP(A32,dataset_2!$A$2:$G$611,7,0) -> 182 | R32: =IF(COUNTA(A32:P32)=16,"OK","CHECK") -> OK | S32: =COUNTIF(R32:R640,"CHECK") -> 5 | T32: =IF(N32+O32=P32,"OK","Error") -> OK | U32: =COUNTIF($A$2:$A$1001,A32) -> 1
A33: 730 | B33: 40576 | C33: 1 | D33: 0 | E33: 2 | F33: 18 | G33: =FALSE() -> FALSE | H33: 3 | I33: 1 | J33: 0.34 | K33: 0.2879 | L33: 0.42 | M33: 0.5522 | N33: 7 | O33: 175 | P33: 182 | R33: =IF(COUNTA(A33:P33)=16,"OK","CHECK") -> OK | S33: =COUNTIF(R33:R641,"CHECK") -> 5 | T33: =IF(N33+O33=P33,"OK","Error") -> OK | U33: =COUNTIF($A$2:$A$1001,A33) -> 1
A34: 819 | B34: 40580 | C34: 1 | D34: 0 | E34: 2 | F34: 13 | G34: =FALSE() -> FALSE | H34: 0 | I34: 1 | J34: 0.34 | K34: 0.3636 | L34: 0.46 | M34: 0 | N34: 47 | O34: 135 | P34: 182 | R34: =IF(COUNTA(A34:P34)=16,"OK","CHECK") -> OK | S34: =COUNTIF(R34:R642,"CHECK") -> 5 | T34: =IF(N34+O34=P34,"OK","Error") -> OK | U34: =COUNTIF($A$2:$A$1001,A34) -> 1
A35: 821 | B35: 40580 | C35: 1 | D35: 0 | E35: 2 | F35: 15 | G35: =FALSE() -> FALSE | H35: 0 | I35: 1 | J35: 0.34 | K35: 0.3485 | L35: 0.46 | M35: 0.0896 | N35: 52 | O35: 130 | P35: 182 | R35: =IF(COUNTA(A35:P35)=16,"OK","CHECK") -> OK | S35: =COUNTIF(R35:R643,"CHECK") -> 5 | T35: =IF(N35+O35=P35,"OK","Error") -> OK | U35: =COUNTIF($A$2:$A$1001,A35) -> 1
A36: =dataset_1!A78 -> 77 | B36: =dataset_1!B78 -> 40547 | C36: =dataset_1!C78 -> 1 | D36: =dataset_1!D78 -> 0 | E36: =dataset_1!E78 -> 1 | F36: =dataset_1!F78 -> 8 | G36: =dataset_1!G78 -> FALSE | H36: =dataset_1!H78 -> 2 | ... J36: =dataset_1!J78 -> 0.14 | K36: =VLOOKUP(A36,dataset_2!$A$2:$G$611,2,0) -> 0.1515 | L36: =VLOOKUP(A36,dataset_2!$A$2:$G$611,3,0) -> 0.69 | M36: =VLOOKUP(A36,dataset_2!$A$2:$G$611,4,0) -> 0.1642 | N36: =VLOOKUP(A36,dataset_2!$A$2:$G$611,5,0) -> 2 | O36: =VLOOKUP(A36,dataset_2!$A$2:$G$611,6,0) -> 177 | P36: =VLOOKUP(A36,dataset_2!$A$2:$G$611,7,0) -> 179 | R36: =IF(COUNTA(A36:P36)=16,"OK","CHECK") -> OK | S36: =COUNTIF(R36:R644,"CHECK") -> 5 | T36: =IF(N36+O36=P36,"OK","Error") -> OK | U36: =COUNTIF($A$2:$A$1001,A36) -> 1
A37: =dataset_1!A228 -> 227 | B37: =dataset_1!B228 -> 40553 | C37: =dataset_1!C228 -> 1 | D37: =dataset_1!D228 -> 0 | E37: =dataset_1!E228 -> 1 | F37: =dataset_1!F228 -> 17 | G37: =dataset_1!G228 -> FALSE | H37: =dataset_1!H228 -> 1 | ... J37: =dataset_1!J228 -> 0.2 | K37: =VLOOKUP(A37,dataset_2!$A$2:$G$611,2,0) -> 0.2273 | L37: =VLOOKUP(A37,dataset_2!$A$2:$G$611,3,0) -> 0.4 | M37: =VLOOKUP(A37,dataset_2!$A$2:$G$611,4,0) -> 0.1045 | N37: =VLOOKUP(A37,dataset_2!$A$2:$G$611,5,0) -> 4 | O37: =VLOOKUP(A37,dataset_2!$A$2:$G$611,6,0) -> 174 | P37: =VLOOKUP(A37,dataset_2!$A$2:$G$611,7,0) -> 178 | R37: =IF(COUNTA(A37:P37)=16,"OK","CHECK") -> OK | S37: =COUNTIF(R37:R645,"CHECK") -> 5 | T37: =IF(N37+O37=P37,"OK","Error") -> OK | U37: =COUNTIF($A$2:$A$1001,A37) -> 1
A38: 908 | B38: 40584 | C38: 1 | D38: 0 | E38: 2 | F38: 8 | G38: =FALSE() -> FALSE | H38: 4 | I38: 1 | J38: 0.1 | K38: 0.0758 | L38: 0.49 | M38: 0.3284 | N38: 5 | O38: 173 | P38: 178 | R38: =IF(COUNTA(A38:P38)=16,"OK","CHECK") -> OK | S38: =COUNTIF(R38:R646,"CHECK") -> 5 | T38: =IF(N38+O38=P38,"OK","Error") -> OK | U38: =COUNTIF($A$2:$A$1001,A38) -> 1
A39: =dataset_1!A534 -> 533 | B39: =dataset_1!B534 -> 40567 | C39: =dataset_1!C534 -> 1 | D39: =dataset_1!D534 -> 0 | E39: =dataset_1!E534 -> 1 | F39: =dataset_1!F534 -> 8 | G39: =dataset_1!G534 -> FALSE | H39: =dataset_1!H534 -> 1 | ... J39: =dataset_1!J534 -> 0.04 | K39: =VLOOKUP(A39,dataset_2!$A$2:$G$611,2,0) -> 0.1364 | L39: =VLOOKUP(A39,dataset_2!$A$2:$G$611,3,0) -> 0.49 | M39: =VLOOKUP(A39,dataset_2!$A$2:$G$611,4,0) -> 0 | N39: =VLOOKUP(A39,dataset_2!$A$2:$G$611,5,0) -> 6 | O39: =VLOOKUP(A39,dataset_2!$A$2:$G$611,6,0) -> 171 | P39: =VLOOKUP(A39,dataset_2!$A$2:$G$611,7,0) -> 177 | R39: =IF(COUNTA(A39:P39)=16,"OK","CHECK") -> OK | S39: =COUNTIF(R39:R647,"CHECK") -> 5 | T39: =IF(N39+O39=P39,"OK","Error") -> OK | U39: =COUNTIF($A$2:$A$1001,A39) -> 1
A40: 705 | B40: 40575 | C40: 1 | D40: 0 | E40: 2 | F40: 17 | G40: =FALSE() -> FALSE | H40: 2 | I40: 2 | J40: 0.24 | K40: 0.2879 | L40: 0.75 | M40: 0 | N40: 4 | O40: 172 | P40: 176 | R40: =IF(COUNTA(A40:P40)=16,"OK","CHECK") -> OK | S40: =COUNTIF(R40:R648,"CHECK") -> 5 | T40: =IF(N40+O40=P40,"OK","Error") -> OK | U40: =COUNTIF($A$2:$A$1001,A40) -> 1
...

Sheet Analysis
A1: Basic Statistics | J1: Statistical Analysis | K1: Value
A2: Total Bike Rentals | B2: =SUM(dataset_A!P2:P1001) -> 58304 | J2: Total Rentals | K2: =SUM(dataset_A!P2:P1001) -> 58304
A3: Average Bike Rentals | B3: =AVERAGE(dataset_A!P2:P1001) -> 58.304 | J3: Average Rentals | K3: =AVERAGE(dataset_A!P2:P1001) -> 58.304
A4: Number of Records | B4: =COUNT(dataset_A!P2:P1001) -> 1000 | J4: Minimum Rentals | K4: =MIN(dataset_A!P2:P1001) -> 1
A5: Minimum Rentals | B5: =MIN(dataset_A!P2:P1001) -> 1 | J5: Maximum Rentals | K5: =MAX(dataset_A!P2:P1001) -> 249
A6: Maximum Rentals | B6: =MAX(dataset_A!P2:P1001) -> 249 | J6: Standard Deviation | K6: =STDEV(dataset_A!P2:P1001) -> 50.985558
J7: Temperature-Demand Correlation | K7: =CORREL(dataset_A!J2:J1001,dataset_A!P2:P1001) -> 0.22929155
A8: Text Functions
A9: Year | B9: =YEAR(dataset_A!B2) -> 2011 | J9: Weekend Records | K9: =COUNTIF(feature_engineering!G2:GC91001,"Weekend") -> 330
A10: Date | B10: =RIGHT(TEXT(dataset_A!B2,"YYYY-MM-DD"),2) -> 20 | J10: Weekday Records | K10: =COUNTIF(feature_engineering!G2:G1001,"Weekday") -> 670
A11: Length | B11: =LEN(TEXT(dataset_A!B2,"YYYY-MM-DD")) -> 10
J12: Weekend Demad | K12: =SUMIF(feature_engineering!G2:G1001,"Weekend",feature_engineering!M2:M1001) -> 15869
A13: Data Quality Check | B13: Result | C13: Status | J13: Weekday Demand | K13: =SUMIF(feature_engineering!G2:G1001,"Weekday",feature_engineering!M2:M1001) -> 42435
A14: Total Records | B14: =COUNT(dataset_A!A2:A1001) -> 1000 | C14: =IF(B14=1000,"Pass","Check") -> Pass
A15: Total Columns | B15: =COUNTA(dataset_A!A1:P1) -> 16 | C15: =IF(B15=16,"Pass","Check") -> Pass
A16: Missing Values | B16: =COUNTBLANK(dataset_A!A2:P1001) -> 11 | C16: =IF(B16=0,"Pass","Check") -> Check
A17: Duplicate Instant | B17: {=SUMPRODUCT(COUNTIF(dataset_A!A2:A1001,dataset_A!A2:A1001)>1)} -> 0 | C17: =IF(B17=0,"Pass","Check") -> Pass
A18: Demand Check | B18: =IF(N2+O2=P2,"Ok","Error") -> Ok | C18: =IF(B18="Ok","Pass","Check") -> Pass
A19: First Instant | B19: =MIN(dataset_A!A2:A1001) -> 1
A20: Last Instant | B20: =MAX(dataset_A!A2:A1001) -> 1000
A21: Index-Match-Check | B21: =COUNTIF(feature_engineering!T2:T1001,"Check") -> 0 | C21: =IF(B21=0,"Pass","Check") -> Pass

Sheet Macro_Control
A1: Bike Sharing Automation Control
A3: Automation Task | B3: Status
A4: Data Quality Check | B4: Completed
A5: Demand Validation | B5: 1000 valid / 0 errors
A6: Dashboard Update | B6: Completed
A8: Last Run | B8: 27-09-2026 15:07:38
A10: Average Demand | B10: 58.304
A11: High Demand Records | B11: 226
A12: Medium Demand Records | B12: 434
A13: Low Demand Records | B13: 340

Sheet feature_engineering
A1: instant | B1: dteday | C1: hr | D1: weekday | E1: holiday | F1: workingday | G1: Day_Type | H1: Hour_Category | I1: Season | J1: Weather | K1: casual | L1: registered | M1: total_demand | N1: Demand_Check | O1: Demand_Category | P1: Saeson_Lookup | Q1: Season_Code | R1: Season_Name | S1: Saeson_Index_Math | T1: Lookup_Check
A2: =dataset_A!A2 -> 440 | B2: =dataset_A!B2 -> 40563 | C2: =dataset_A!F2 -> 8 | D2: =dataset_A!H2 -> 4 | E2: =dataset_A!G2 -> FALSE | F2: =dataset_A!G2 -> FALSE | G2: =IF(OR(D2=0,D2=6),"Weekend","Weekday") -> Weekday | H2: =IF(C2<6,"Night",IF(C2<12,"Morning",IF(C2<18,"Afternoon","Evening"))) -> Morning | I2: =IF(dataset_A!C2=1,"Spring",IF(dataset_A!C2=2,"Summer",IF(dataset_A!C2=3,"Fail","Winter"))) -> Spring | J2: =IF(dataset_A!I2=1,"Clear",IF(dataset_A!I2,"Mist/Cloudy",IF(dataset_A!I2=3,"Light Rain/Snow","Heavy Rain/Snow"))) -> Clear | K2: =dataset_A!N2 -> 2 | L2: =dataset_A!O2 -> 247 | M2: =dataset_A!P2 -> 249 | N2: =IF(K2+L2=M2,"Ok","Error") -> Ok | O2: =IF(M2>Analysis!$B$3*1.5,"High",IF(M2<Analysis!$B$3*0.5,"Low","Medium")) -> High | P2: =VLOOKUP(dataset_A!C2,$Q$2:$R$5,2,0) -> Spring | Q2: 1 | R2: Spring | S2: {=INDEX($R$2:$R$5,MATCH(dataset_A!C2,$Q$2:$Q$5,0))} -> Spring | T2: =IF(P2=S2,"Match","Check") -> Match
A3: =dataset_A!A3 -> 862 | B3: =dataset_A!B3 -> 40582 | C3: =dataset_A!F3 -> 8 | D3: =dataset_A!H3 -> 2 | E3: =dataset_A!G3 -> FALSE | F3: =dataset_A!G3 -> FALSE | G3: =IF(OR(D3=0,D3=6),"Weekend","Weekday") -> Weekday | H3: =IF(C3<6,"Night",IF(C3<12,"Morning",IF(C3<18,"Afternoon","Evening"))) -> Morning | I3: =IF(dataset_A!C3=1,"Spring",IF(dataset_A!C3=2,"Summer",IF(dataset_A!C3=3,"Fail","Winter"))) -> Spring | J3: =IF(dataset_A!I3=1,"Clear",IF(dataset_A!I3,"Mist/Cloudy",IF(dataset_A!I3=3,"Light Rain/Snow","Heavy Rain/Snow"))) -> Clear | K3: =dataset_A!N3 -> 7 | L3: =dataset_A!O3 -> 236 | M3: =dataset_A!P3 -> 243 | N3: =IF(K3+L3=M3,"Ok","Error") -> Ok | O3: =IF(M3>Analysis!$B$3*1.5,"High",IF(M3<Analysis!$B$3*0.5,"Low","Medium")) -> High | P3: =VLOOKUP(dataset_A!C3,$Q$2:$R$5,2,0) -> Spring | Q3: 2 | R3: Summer | S3: {=INDEX($R$2:$R$5,MATCH(dataset_A!C3,$Q$2:$Q$5,0))} -> Spring | T3: =IF(P3=S3,"Match","Check") -> Match
A4: =dataset_A!A4 -> 556 | B4: =dataset_A!B4 -> 40568 | C4: =dataset_A!F4 -> 8 | D4: =dataset_A!H4 -> 2 | E4: =dataset_A!G4 -> FALSE | F4: =dataset_A!G4 -> FALSE | G4: =IF(OR(D4=0,D4=6),"Weekend","Weekday") -> Weekday | H4: =IF(C4<6,"Night",IF(C4<12,"Morning",IF(C4<18,"Afternoon","Evening"))) -> Morning | I4: =IF(dataset_A!C4=1,"Spring",IF(dataset_A!C4=2,"Summer",IF(dataset_A!C4=3,"Fail","Winter"))) -> Spring | J4: =IF(dataset_A!I4=1,"Clear",IF(dataset_A!I4,"Mist/Cloudy",IF(dataset_A!I4=3,"Light Rain/Snow","Heavy Rain/Snow"))) -> Mist/Cloudy | K4: =dataset_A!N4 -> 5 | L4: =dataset_A!O4 -> 233 | M4: =dataset_A!P4 -> 238 | N4: =IF(K4+L4=M4,"Ok","Error") -> Ok | O4: =IF(M4>Analysis!$B$3*1.5,"High",IF(M4<Analysis!$B$3*0.5,"Low","Medium")) -> High | P4: =VLOOKUP(dataset_A!C4,$Q$2:$R$5,2,0) -> Spring | Q4: 3 | R4: Fall | S4: {=INDEX($R$2:$R$5,MATCH(dataset_A!C4,$Q$2:$Q$5,0))} -> Spring | T4: =IF(P4=S4,"Match","Check") -> Match
A5: =dataset_A!A5 -> 838 | B5: =dataset_A!B5 -> 40581 | C5: =dataset_A!F5 -> 8 | D5: =dataset_A!H5 -> 1 | E5: =dataset_A!G5 -> FALSE | F5: =dataset_A!G5 -> FALSE | G5: =IF(OR(D5=0,D5=6),"Weekend","Weekday") -> Weekday | H5: =IF(C5<6,"Night",IF(C5<12,"Morning",IF(C5<18,"Afternoon","Evening"))) -> Morning | I5: =IF(dataset_A!C5=1,"Spring",IF(dataset_A!C5=2,"Summer",IF(dataset_A!C5=3,"Fail","Winter"))) -> Spring | J5: =IF(dataset_A!I5=1,"Clear",IF(dataset_A!I5,"Mist/Cloudy",IF(dataset_A!I5=3,"Light Rain/Snow","Heavy Rain/Snow"))) -> Mist/Cloudy | K5: =dataset_A!N5 -> 7 | L5: =dataset_A!O5 -> 223 | M5: =dataset_A!P5 -> 230 | N5: =IF(K5+L5=M5,"Ok","Error") -> Ok | O5: =IF(M5>Analysis!$B$3*1.5,"High",IF(M5<Analysis!$B$3*0.5,"Low","Medium")) -> High | P5: =VLOOKUP(dataset_A!C5,$Q$2:$R$5,2,0) -> Spring | Q5: 4 | R5: Winter | S5: {=INDEX($R$2:$R$5,MATCH(dataset_A!C5,$Q$2:$Q$5,0))} -> Spring | T5: =IF(P5=S5,"Match","Check") -> Match
A6: =dataset_A!A6 -> 566 | B6: =dataset_A!B6 -> 40568 | C6: =dataset_A!F6 -> 18 | D6: =dataset_A!H6 -> 2 | E6: =dataset_A!G6 -> FALSE | F6: =dataset_A!G6 -> FALSE | G6: =IF(OR(D6=0,D6=6),"Weekend","Weekday") -> Weekday | H6: =IF(C6<6,"Night",IF(C6<12,"Morning",IF(C6<18,"Afternoon","Evening"))) -> Evening | I6: =IF(dataset_A!C6=1,"Spring",IF(dataset_A!C6=2,"Summer",IF(dataset_A!C6=3,"Fail","Winter"))) -> Spring | J6: =IF(dataset_A!I6=1,"Clear",IF(dataset_A!I6,"Mist/Cloudy",IF(dataset_A!I6=3,"Light Rain/Snow","Heavy Rain/Snow"))) -> Mist/Cloudy | K6: =dataset_A!N6 -> 7 | L6: =dataset_A!O6 -> 218 | M6: =dataset_A!P6 -> 225 | N6: =IF(K6+L6=M6,"Ok","Error") -> Ok | O6: =IF(M6>Analysis!$B$3*1.5,"High",IF(M6<Analysis!$B$3*0.5,"Low","Medium")) -> High | P6: =VLOOKUP(dataset_A!C6,$Q$2:$R$5,2,0) -> Spring | S6: {=INDEX($R$2:$R$5,MATCH(dataset_A!C6,$Q$2:$Q$5,0))} -> Spring | T6: =IF(P6=S6,"Match","Check") -> Match
A7: =dataset_A!A7 -> 565 | B7: =dataset_A!B7 -> 40568 | C7: =dataset_A!F7 -> 17 | D7: =dataset_A!H7 -> 2 | E7: =dataset_A!G7 -> FALSE | F7: =dataset_A!G7 -> FALSE | G7: =IF(OR(D7=0,D7=6),"Weekend","Weekday") -> Weekday | H7: =IF(C7<6,"Night",IF(C7<12,"Morning",IF(C7<18,"Afternoon","Evening"))) -> Afternoon | I7: =IF(dataset_A!C7=1,"Spring",IF(dataset_A!C7=2,"Summer",IF(dataset_A!C7=3,"Fail","Winter"))) -> Spring | J7: =IF(dataset_A!I7=1,"Clear",IF(dataset_A!I7,"Mist/Cloudy",IF(dataset_A!I7=3,"Light Rain/Snow","Heavy Rain/Snow"))) -> Clear | K7: =dataset_A!N7 -> 14 | L7: =dataset_A!O7 -> 208 | M7: =dataset_A!P7 -> 222 | N7: =IF(K7+L7=M7,"Ok","Error") -> Ok | O7: =IF(M7>Analysis!$B$3*1.5,"High",IF(M7<Analysis!$B$3*0.5,"Low","Medium")) -> High | P7: =VLOOKUP(dataset_A!C7,$Q$2:$R$5,2,0) -> Spring | S7: {=INDEX($R$2:$R$5,MATCH(dataset_A!C7,$Q$2:$Q$5,0))} -> Spring | T7: =IF(P7=S7,"Match","Check") -> Match
A8: =dataset_A!A8 -> 766 | B8: =dataset_A!B8 -> 40578 | C8: =dataset_A!F8 -> 8 | D8: =dataset_A!H8 -> 5 | E8: =dataset_A!G8 -> FALSE | F8: =dataset_A!G8 -> FALSE | G8: =IF(OR(D8=0,D8=6),"Weekend","Weekday") -> Weekday | H8: =IF(C8<6,"Night",IF(C8<12,"Morning",IF(C8<18,"Afternoon","Evening"))) -> Morning | I8: =IF(dataset_A!C8=1,"Spring",IF(dataset_A!C8=2,"Summer",IF(dataset_A!C8=3,"Fail","Winter"))) -> Spring | J8: =IF(dataset_A!I8=1,"Clear",IF(dataset_A!I8,"Mist/Cloudy",IF(dataset_A!I8=3,"Light Rain/Snow","Heavy Rain/Snow"))) -> Clear | K8: =dataset_A!N8 -> 3 | L8: =dataset_A!O8 -> 217 | M8: =dataset_A!P8 -> 220 | N8: =IF(K8+L8=M8,"Ok","Error") -> Ok | O8: =IF(M8>Analysis!$B$3*1.5,"High",IF(M8<Analysis!$B$3*0.5,"Low","Medium")) -> High | P8: =VLOOKUP(dataset_A!C8,$Q$2:$R$5,2,0) -> Spring | S8: {=INDEX($R$2:$R$5,MATCH(dataset_A!C8,$Q$2:$Q$5,0))} -> Spring | T8: =IF(P8=S8,"Match","Check") -> Match
A9: =dataset_A!A9 -> 123 | B9: =dataset_A!B9 -> 40549 | C9: =dataset_A!F9 -> 8 | D9: =dataset_A!H9 -> 4 | E9: =dataset_A!G9 -> FALSE | F9: =dataset_A!G9 -> FALSE | G9: =IF(OR(D9=0,D9=6),"Weekend","Weekday") -> Weekday | H9: =IF(C9<6,"Night",IF(C9<12,"Morning",IF(C9<18,"Afternoon","Evening"))) -> Morning | I9: =IF(dataset_A!C9=1,"Spring",IF(dataset_A!C9=2,"Summer",IF(dataset_A!C9=3,"Fail","Winter"))) -> Spring | J9: =IF(dataset_A!I9=1,"Clear",IF(dataset_A!I9,"Mist/Cloudy",IF(dataset_A!I9=3,"Light Rain/Snow","Heavy Rain/Snow"))) -> Clear | K9: =dataset_A!N9 -> 3 | L9: =dataset_A!O9 -> 216 | M9: =dataset_A!P9 -> 219 | N9: =IF(K9+L9=M9,"Ok","Error") -> Ok | O9: =IF(M9>Analysis!$B$3*1.5,"High",IF(M9<Analysis!$B$3*0.5,"Low","Medium")) -> High | P9: =VLOOKUP(dataset_A!C9,$Q$2:$R$5,2,0) -> Spring | S9: {=INDEX($R$2:$R$5,MATCH(dataset_A!C9,$Q$2:$Q$5,0))} -> Spring | T9: =IF(P9=S9,"Match","Check") -> Match
A10: =dataset_A!A10 -> 240 | B10: =dataset_A!B10 -> 40554 | C10: =dataset_A!F10 -> 8 | D10: =dataset_A!H10 -> 2 | E10: =dataset_A!G10 -> FALSE | F10: =dataset_A!G10 -> FALSE | G10: =IF(OR(D10=0,D10=6),"Weekend","Weekday") -> Weekday | H10: =IF(C10<6,"Night",IF(C10<12,"Morning",IF(C10<18,"Afternoon","Evening"))) -> Morning | I10: =IF(dataset_A!C10=1,"Spring",IF(dataset_A!C10=2,"Summer",IF(dataset_A!C10=3,"Fail","Winter"))) -> Spring | J10: =IF(dataset_A!I10=1,"Clear",IF(dataset_A!I10,"Mist/Cloudy",IF(dataset_A!I10=3,"Light Rain/Snow","Heavy Rain/Snow"))) -> Mist/Cloudy | K10: =dataset_A!N10 -> 3 | L10: =dataset_A!O10 -> 214 | M10: =dataset_A!P10 -> 217 | N10: =IF(K10+L10=M10,"Ok","Error") -> Ok | O10: =IF(M10>Analysis!$B$3*1.5,"High",IF(M10<Analysis!$B$3*0.5,"Low","Medium")) -> High | P10: =VLOOKUP(dataset_A!C10,$Q$2:$R$5,2,0) -> Spring | S10: {=INDEX($R$2:$R$5,MATCH(dataset_A!C10,$Q$2:$Q$5,0))} -> Spring | T10: =IF(P10=S10,"Match","Check") -> Match
A11: =dataset_A!A11 -> 464 | B11: =dataset_A!B11 -> 40564 | C11: =dataset_A!F11 -> 8 | D11: =dataset_A!H11 -> 5 | E11: =dataset_A!G11 -> FALSE | F11: =dataset_A!G11 -> FALSE | G11: =IF(OR(D11=0,D11=6),"Weekend","Weekday") -> Weekday | H11: =IF(C11<6,"Night",IF(C11<12,"Morning",IF(C11<18,"Afternoon","Evening"))) -> Morning | I11: =IF(dataset_A!C11=1,"Spring",IF(dataset_A!C11=2,"Summer",IF(dataset_A!C11=3,"Fail","Winter"))) -> Spring | J11: =IF(dataset_A!I11=1,"Clear",IF(dataset_A!I11,"Mist/Cloudy",IF(dataset_A!I11=3,"Light Rain/Snow","Heavy Rain/Snow"))) -> Clear | K11: =dataset_A!N11 -> 7 | L11: =dataset_A!O11 -> 210 | M11: =dataset_A!P11 -> 217 | N11: =IF(K11+L11=M11,"Ok","Error") -> Ok | O11: =IF(M11>Analysis!$B$3*1.5,"High",IF(M11<Analysis!$B$3*0.5,"Low","Medium")) -> High | P11: =VLOOKUP(dataset_A!C11,$Q$2:$R$5,2,0) -> Spring | S11: {=INDEX($R$2:$R$5,MATCH(dataset_A!C11,$Q$2:$Q$5,0))} -> Spring | T11: =IF(P11=S11,"Match","Check") -> Match
A12: =dataset_A!A12 -> 847 | B12: =dataset_A!B12 -> 40581 | C12: =dataset_A!F12 -> 17 | D12: =dataset_A!H12 -> 1 | E12: =dataset_A!G12 -> FALSE | F12: =dataset_A!G12 -> FALSE | G12: =IF(OR(D12=0,D12=6),"Weekend","Weekday") -> Weekday | H12: =IF(C12<6,"Night",IF(C12<12,"Morning",IF(C12<18,"Afternoon","Evening"))) -> Afternoon | I12: =IF(dataset_A!C12=1,"Spring",IF(dataset_A!C12=2,"Summer",IF(dataset_A!C12=3,"Fail","Winter"))) -> Spring | J12: =IF(dataset_A!I12=1,"Clear",IF(dataset_A!I12,"Mist/Cloudy",IF(dataset_A!I12=3,"Light Rain/Snow","Heavy Rain/Snow"))) -> Mist/Cloudy | K12: =dataset_A!N12 -> 9 | L12: =dataset_A!O12 -> 207 | M12: =dataset_A!P12 -> 216 | N12: =IF(K12+L12=M12,"Ok","Error") -> Ok | O12: =IF(M12>Analysis!$B$3*1.5,"High",IF(M12<Analysis!$B$3*0.5,"Low","Medium")) -> High | P12: =VLOOKUP(dataset_A!C12,$Q$2:$R$5,2,0) -> Spring | S12: {=INDEX($R$2:$R$5,MATCH(dataset_A!C12,$Q$2:$Q$5,0))} -> Spring | T12: =IF(P12=S12,"Match","Check") -> Match
A13: =dataset_A!A13 -> 930 | B13: =dataset_A!B13 -> 40585 | C13: =dataset_A!F13 -> 8 | D13: =dataset_A!H13 -> 5 | E13: =dataset_A!G13 -> FALSE | F13: =dataset_A!G13 -> FALSE | G13: =IF(OR(D13=0,D13=6),"Weekend","Weekday") -> Weekday | H13: =IF(C13<6,"Night",IF(C13<12,"Morning",IF(C13<18,"Afternoon","Evening"))) -> Morning | I13: =IF(dataset_A!C13=1,"Spring",IF(dataset_A!C13=2,"Summer",IF(dataset_A!C13=3,"Fail","Winter"))) -> Spring | J13: =IF(dataset_A!I13=1,"Clear",IF(dataset_A!I13,"Mist/Cloudy",IF(dataset_A!I13=3,"Light Rain/Snow","Heavy Rain/Snow"))) -> Clear | K13: =dataset_A!N13 -> 4 | L13: =dataset_A!O13 -> 212 | M13: =dataset_A!P13 -> 216 | N13: =IF(K13+L13=M13,"Ok","Error") -> Ok | O13: =IF(M13>Analysis!$B$3*1.5,"High",IF(M13<Analysis!$B$3*0.5,"Low","Medium")) -> High | P13: =VLOOKUP(dataset_A!C13,$Q$2:$R$5,2,0) -> Spring | S13: {=INDEX($R$2:$R$5,MATCH(dataset_A!C13,$Q$2:$Q$5,0))} -> Spring | T13: =IF(P13=S13,"Match","Check") -> Match
A14: =dataset_A!A14 -> 449 | B14: =dataset_A!B14 -> 40563 | C14: =dataset_A!F14 -> 17 | D14: =dataset_A!H14 -> 4 | E14: =dataset_A!G14 -> FALSE | F14: =dataset_A!G14 -> FALSE | G14: =IF(OR(D14=0,D14=6),"Weekend","Weekday") -> Weekday | H14: =IF(C14<6,"Night",IF(C14<12,"Morning",IF(C14<18,"Afternoon","Evening"))) -> Afternoon | I14: =IF(dataset_A!C14=1,"Spring",IF(dataset_A!C14=2,"Summer",IF(dataset_A!C14=3,"Fail","Winter"))) -> Spring | J14: =IF(dataset_A!I14=1,"Clear",IF(dataset_A!I14,"Mist/Cloudy",IF(dataset_A!I14=3,"Light Rain/Snow","Heavy Rain/Snow"))) -> Mist/Cloudy | K14: =dataset_A!N14 -> 8 | L14: =dataset_A!O14 -> 207 | M14: =dataset_A!P14 -> 215 | N14: =IF(K14+L14=M14,"Ok","Error") -> Ok | O14: =IF(M14>Analysis!$B$3*1.5,"High",IF(M14<Analysis!$B$3*0.5,"Low","Medium")) -> High | P14: =VLOOKUP(dataset_A!C14,$Q$2:$R$5,2,0) -> Spring | S14: {=INDEX($R$2:$R$5,MATCH(dataset_A!C14,$Q$2:$Q$5,0))} -> Spring | T14: =IF(P14=S14,"Match","Check") -> Match
A15: =dataset_A!A15 -> 86 | B15: =dataset_A!B15 -> 40547 | C15: =dataset_A!F15 -> 17 | D15: =dataset_A!H15 -> 2 | E15: =dataset_A!G15 -> FALSE | F15: =dataset_A!G15 -> FALSE | G15: =IF(OR(D15=0,D15=6),"Weekend","Weekday") -> Weekday | H15: =IF(C15<6,"Night",IF(C15<12,"Morning",IF(C15<18,"Afternoon","Evening"))) -> Afternoon | I15: =IF(dataset_A!C15=1,"Spring",IF(dataset_A!C15=2,"Summer",IF(dataset_A!C15=3,"Fail","Winter"))) -> Spring | J15: =IF(dataset_A!I15=1,"Clear",IF(dataset_A!I15,"Mist/Cloudy",IF(dataset_A!I15=3,"Light Rain/Snow","Heavy Rain/Snow"))) -> Clear | K15: =dataset_A!N15 -> 10 | L15: =dataset_A!O15 -> 202 | M15: =dataset_A!P15 -> 212 | N15: =IF(K15+L15=M15,"Ok","Error") -> Ok | O15: =IF(M15>Analysis!$B$3*1.5,"High",IF(M15<Analysis!$B$3*0.5,"Low","Medium")) -> High | P15: =VLOOKUP(dataset_A!C15,$Q$2:$R$5,2,0) -> Spring | S15: {=INDEX($R$2:$R$5,MATCH(dataset_A!C15,$Q$2:$Q$5,0))} -> Spring | T15: =IF(P15=S15,"Match","Check") -> Match
A16: =dataset_A!A16 -> 939 | B16: =dataset_A!B16 -> 40585 | C16: =dataset_A!F16 -> 17 | D16: =dataset_A!H16 -> 5 | E16: =dataset_A!G16 -> FALSE | F16: =dataset_A!G16 -> FALSE | G16: =IF(OR(D16=0,D16=6),"Weekend","Weekday") -> Weekday | H16: =IF(C16<6,"Night",IF(C16<12,"Morning",IF(C16<18,"Afternoon","Evening"))) -> Afternoon | I16: =IF(dataset_A!C16=1,"Spring",IF(dataset_A!C16=2,"Summer",IF(dataset_A!C16=3,"Fail","Winter"))) -> Spring | J16: =IF(dataset_A!I16=1,"Clear",IF(dataset_A!I16,"Mist/Cloudy",IF(dataset_A!I16=3,"Light Rain/Snow","Heavy Rain/Snow"))) -> Clear | K16: =dataset_A!N16 -> 18 | L16: =dataset_A!O16 -> 193 | M16: =dataset_A!P16 -> 211 | N16: =IF(K16+L16=M16,"Ok","Error") -> Ok | O16: =IF(M16>Analysis!$B$3*1.5,"High",IF(M16<Analysis!$B$3*0.5,"Low","Medium")) -> High | P16: =VLOOKUP(dataset_A!C16,$Q$2:$R$5,2,0) -> Spring | S16: {=INDEX($R$2:$R$5,MATCH(dataset_A!C16,$Q$2:$Q$5,0))} -> Spring | T16: =IF(P16=S16,"Match","Check") -> Match
A17: =dataset_A!A17 -> 146 | B17: =dataset_A!B17 -> 40550 | C17: =dataset_A!F17 -> 8 | D17: =dataset_A!H17 -> 5 | E17: =dataset_A!G17 -> FALSE | F17: =dataset_A!G17 -> FALSE | G17: =IF(OR(D17=0,D17=6),"Weekend","Weekday") -> Weekday | H17: =IF(C17<6,"Night",IF(C17<12,"Morning",IF(C17<18,"Afternoon","Evening"))) -> Morning | I17: =IF(dataset_A!C17=1,"Spring",IF(dataset_A!C17=2,"Summer",IF(dataset_A!C17=3,"Fail","Winter"))) -> Spring | J17: =IF(dataset_A!I17=1,"Clear",IF(dataset_A!I17,"Mist/Cloudy",IF(dataset_A!I17=3,"Light Rain/Snow","Heavy Rain/Snow"))) -> Clear | K17: =dataset_A!N17 -> 20 | L17: =dataset_A!O17 -> 190 | M17: =dataset_A!P17 -> 210 | N17: =IF(K17+L17=M17,"Ok","Error") -> Ok | O17: =IF(M17>Analysis!$B$3*1.5,"High",IF(M17<Analysis!$B$3*0.5,"Low","Medium")) -> High | P17: =VLOOKUP(dataset_A!C17,$Q$2:$R$5,2,0) -> Spring | S17: {=INDEX($R$2:$R$5,MATCH(dataset_A!C17,$Q$2:$Q$5,0))} -> Spring | T17: =IF(P17=S17,"Match","Check") -> Match
... A1001: =dataset_A!A1001 -> 951 | B1001: =dataset_A!B1001 -> 40586 | C1001: =dataset_A!F1001 -> 5 | D1001: =dataset_A!H1001 -> 6 | E1001: =dataset_A!G1001 -> FALSE | F1001: =dataset_A!G1001 -> FALSE | G1001: =IF(OR(D1001=0,D1001=6),"Weekend","Weekday") -> Weekend | H1001: =IF(C1001<6,"Night",IF(C1001<12,"Morning",IF(C1001<18,"Afternoon","Evening"))) -> Night | I1001: =IF(dataset_A!C1001=1,"Spring",IF(dataset_A!C1001=2,"Summer",IF(dataset_A!C1001=3,"Fail","Winter"))) -> Spring | J1001: =IF(dataset_A!I1001=1,"Clear",IF(dataset_A!I1001,"Mist/Cloudy",IF(dataset_A!I1001=3,"Light Rain/Snow","Heavy Rain/Snow"))) -> Clear | K1001: =dataset_A!N1001 -> 0 | L1001: =dataset_A!O1001 -> 1 | M1001: =dataset_A!P1001 -> 1 | N1001: =IF(K1001+L1001=M1001,"Ok","Error") -> Ok | O1001: =IF(M1001>Analysis!$B$3*1.5,"High",IF(M1001<Analysis!$B$3*0.5,"Low","Medium")) -> Low | P1001: =VLOOKUP(dataset_A!C1001,$Q$2:$R$5,2,0) -> Spring | S1001: {=INDEX($R$2:$R$5,MATCH(dataset_A!C1001,$Q$2:$Q$5,0))} -> Spring | T1001: =IF(P1001=S1001,"Match","Check") -> Match

Sheet Pivot Tables
A1: Demand by Hour | D1: Demand by Weekday | G1: Casual vs Registered Users by Hour
K2: total demand by Hour Category. | N2: Demand by Category
K11: Bike Demand Trend Over Time
D13: Demand by Season
D20: Holiday vs Non-Holiday Demand
A29: Demand by Weather

Sheet Dashboard
A1: Bike Sharing Demand Analysis Dashboard
A4: Total Rentals | E4: Average Rentals | I4: Maximum Rentals | M4: Temperature Correlation | Q4: Filters
A5: =Analysis!K2 -> 58304 | E5: =Analysis!K3 -> 58.304 | I5: =Analysis!K5 -> 249 | M5: =Analysis!K7 -> 0.22929155
W120: Demand by Hour | Z120: Demand by Weekday | AC120: Casual vs Registered Users by Hour
AG121: total demand by Hour Category. | AJ121: Demand by Category
AM125: Weather | AN125: Total Demand
AM126: Clear | AN126: =B2
AM127: Mist / Cloudy | AN127: =B3
AM128: Light Rain / Snow | AN128: =B4
AM129: Heavy Rain / Snow | AN129: =B5
AG130: Bike Demand Trend Over Time
Z132: Demand by Season
Z139: Holiday vs Non-Holiday Demand
W148: Demand by Weather

Sheet Forecast_Anomaly
A1: =IFERROR(__xludf.DUMMYFUNCTION("QUERY(dataset_A!B2:P1001,""select B, sum(P) where B is not null group by B order by B label B 'Date', sum(P) 'Total Demand'"",0)"),"Date") -> Date | B1: =IFERROR(__xludf.DUMMYFUNCTION("""COMPUTED_VALUE"""),"Total Demand") -> Total Demand | D1: Number of Days | F1: Forecast | H1: Z-Score | I1: Anomaly | K1: Anomaly Count | L1: Average Daily Demand | M1: Maximum Daily Demand
A2: =IFERROR(__xludf.DUMMYFUNCTION("""COMPUTED_VALUE"""),40544.0) -> 40544 | B2: =IFERROR(__xludf.DUMMYFUNCTION("""COMPUTED_VALUE"""),985.0) -> 985 | D2: =COUNTA(A1:A1000) -> 46 | F2: =_xlfn.FORECAST.LINEAR(A46,B1:B46,A1:A46) -> 1378.1343 | H2: =(B2-AVERAGE($B$2:$B$47))/STDEV($B$2:$B$47) -> -0.79115119 | I2: =IF(ABS(H2)>=3,"Anomaly","Normal") -> Normal | K2: =COUNTIF(I2:I47,"Anomaly") -> 0 | L2: =AVERAGE(B2:B47) -> 1295.6444 | M2: =MAX(B2:B47) -> 1985
A3: =IFERROR(__xludf.DUMMYFUNCTION("""COMPUTED_VALUE"""),40545.0) -> 40545 | B3: =IFERROR(__xludf.DUMMYFUNCTION("""COMPUTED_VALUE"""),801.0) -> 801 | H3: =(B3-AVERAGE($B$2:$B$47))/STDEV($B$2:$B$47) -> -1.2597635 | I3: =IF(ABS(H3)>=3,"Anomaly","Normal") -> Normal
